2022/10/30, 13:47:58 INFO Scheduler started
2022/10/30, 13:49:43 INFO Бот запущен None id 1095956902
2022/10/30, 13:49:57 INFO Пользователь выбрал работать
2022/10/30, 13:51:14 INFO Received signal 2 (SIGINT), stopping...
2022/10/30, 13:51:14 INFO Scheduler has been shut down
2022/10/30, 13:53:58 INFO Scheduler started
2022/10/30, 13:54:10 INFO Бот запущен None id 1095956902
2022/10/30, 13:54:12 INFO Пользователь выбрал работать
2022/10/30, 13:54:30 INFO Received signal 2 (SIGINT), stopping...
2022/10/30, 13:54:30 INFO Scheduler has been shut down
2022/10/30, 13:56:22 INFO Scheduler started
2022/10/30, 13:56:30 INFO Бот запущен None id 1095956902
2022/10/30, 13:56:32 INFO Пользователь выбрал работать
2022/10/30, 13:59:52 INFO Received signal 2 (SIGINT), stopping...
2022/10/30, 13:59:52 INFO Scheduler has been shut down
2022/10/30, 14:00:08 INFO Scheduler started
2022/10/30, 14:00:17 INFO Бот запущен None id 1095956902
2022/10/30, 14:00:20 INFO Пользователь выбрал работать
2022/10/30, 14:01:01 INFO Received signal 2 (SIGINT), stopping...
2022/10/30, 14:01:01 INFO Scheduler has been shut down
2022/10/30, 14:01:38 INFO Scheduler started
2022/10/30, 14:01:44 INFO Бот запущен None id 1095956902
2022/10/30, 14:01:46 INFO Пользователь выбрал работать
2022/10/30, 14:02:36 INFO Received signal 2 (SIGINT), stopping...
2022/10/30, 14:02:36 INFO Scheduler has been shut down
2022/10/30, 14:02:45 INFO Scheduler started
2022/10/30, 14:02:54 INFO Бот запущен None id 1095956902
2022/10/30, 14:02:57 INFO Пользователь выбрал работать
2022/10/30, 14:04:32 INFO Received signal 2 (SIGINT), stopping...
2022/10/30, 14:04:32 INFO Scheduler has been shut down
2022/10/30, 14:04:36 INFO Scheduler started
2022/10/30, 14:04:42 INFO Бот запущен None id 1095956902
2022/10/30, 14:04:44 INFO Пользователь выбрал работать
2022/10/30, 14:06:07 INFO Received signal 2 (SIGINT), stopping...
2022/10/30, 14:06:07 INFO Scheduler has been shut down
2022/10/30, 14:26:24 WARNING Exiting immediately!
2022/10/30, 14:29:48 INFO Scheduler started
2022/10/30, 14:29:56 INFO Бот запущен None id 1095956902
2022/10/30, 14:29:59 INFO Пользователь выбрал: Выход.
2022/10/30, 14:29:59 INFO Завершение работы.
2022/10/30, 14:30:06 INFO Бот запущен None id 1095956902
2022/10/30, 14:30:08 INFO Пользователь выбрал работать
2022/10/30, 14:31:34 INFO Received signal 2 (SIGINT), stopping...
2022/10/30, 14:31:34 INFO Scheduler has been shut down
2022/10/30, 14:32:38 WARNING Exiting immediately!
2022/10/30, 14:32:41 INFO Scheduler started
2022/10/30, 14:32:48 INFO Бот запущен None id 1095956902
2022/10/30, 14:32:50 INFO Пользователь выбрал работать
2022/10/30, 14:33:48 INFO Received signal 2 (SIGINT), stopping...
2022/10/30, 14:33:48 INFO Scheduler has been shut down
2022/10/30, 14:33:54 WARNING Exiting immediately!
2022/10/30, 14:33:57 INFO Scheduler started
2022/10/30, 14:34:10 INFO Бот запущен None id 1095956902
2022/10/30, 14:34:13 INFO Пользователь выбрал работать
2022/10/30, 14:35:38 INFO Received signal 2 (SIGINT), stopping...
2022/10/30, 14:35:38 INFO Scheduler has been shut down
2022/10/30, 14:35:38 WARNING Exiting immediately!
2022/10/30, 14:35:40 INFO Scheduler started
2022/10/30, 14:35:48 INFO Бот запущен None id 1095956902
2022/10/30, 14:35:50 INFO Пользователь выбрал работать
2022/10/30, 16:14:46 ERROR No error handlers are registered, logging exception.
Traceback (most recent call last):
  File "C:\Users\MRU024\Desktop\ДЕНИС\PYTHON\sem9\venv\lib\site-packages\telegram\vendor\ptb_urllib3\urllib3\connectionpool.py", line 402, in _make_request
    six.raise_from(e, None)
  File "<string>", line 2, in raise_from
  File "C:\Users\MRU024\Desktop\ДЕНИС\PYTHON\sem9\venv\lib\site-packages\telegram\vendor\ptb_urllib3\urllib3\connectionpool.py", line 398, in _make_request
    httplib_response = conn.getresponse()
  File "C:\Users\MRU024\AppData\Local\Programs\Python\Python310\lib\http\client.py", line 1374, in getresponse
    response.begin()
  File "C:\Users\MRU024\AppData\Local\Programs\Python\Python310\lib\http\client.py", line 318, in begin
    version, status, reason = self._read_status()
  File "C:\Users\MRU024\AppData\Local\Programs\Python\Python310\lib\http\client.py", line 279, in _read_status
    line = str(self.fp.readline(_MAXLINE + 1), "iso-8859-1")
  File "C:\Users\MRU024\AppData\Local\Programs\Python\Python310\lib\socket.py", line 705, in readinto
    return self._sock.recv_into(b)
  File "C:\Users\MRU024\AppData\Local\Programs\Python\Python310\lib\ssl.py", line 1274, in recv_into
    return self.read(nbytes, buffer)
  File "C:\Users\MRU024\AppData\Local\Programs\Python\Python310\lib\ssl.py", line 1130, in read
    return self._sslobj.read(len, buffer)
TimeoutError: The read operation timed out

During handling of the above exception, another exception occurred:

Traceback (most recent call last):
  File "C:\Users\MRU024\Desktop\ДЕНИС\PYTHON\sem9\venv\lib\site-packages\telegram\utils\request.py", line 259, in _request_wrapper
    resp = self._con_pool.request(*args, **kwargs)
  File "C:\Users\MRU024\Desktop\ДЕНИС\PYTHON\sem9\venv\lib\site-packages\telegram\vendor\ptb_urllib3\urllib3\request.py", line 68, in request
    return self.request_encode_body(method, url, fields=fields,
  File "C:\Users\MRU024\Desktop\ДЕНИС\PYTHON\sem9\venv\lib\site-packages\telegram\vendor\ptb_urllib3\urllib3\request.py", line 148, in request_encode_body
    return self.urlopen(method, url, **extra_kw)
  File "C:\Users\MRU024\Desktop\ДЕНИС\PYTHON\sem9\venv\lib\site-packages\telegram\vendor\ptb_urllib3\urllib3\poolmanager.py", line 244, in urlopen
    response = conn.urlopen(method, u.request_uri, **kw)
  File "C:\Users\MRU024\Desktop\ДЕНИС\PYTHON\sem9\venv\lib\site-packages\telegram\vendor\ptb_urllib3\urllib3\connectionpool.py", line 665, in urlopen
    retries = retries.increment(method, url, error=e, _pool=self,
  File "C:\Users\MRU024\Desktop\ДЕНИС\PYTHON\sem9\venv\lib\site-packages\telegram\vendor\ptb_urllib3\urllib3\util\retry.py", line 347, in increment
    raise six.reraise(type(error), error, _stacktrace)
  File "C:\Users\MRU024\Desktop\ДЕНИС\PYTHON\sem9\venv\lib\site-packages\telegram\vendor\ptb_urllib3\urllib3\packages\six.py", line 686, in reraise
    raise value
  File "C:\Users\MRU024\Desktop\ДЕНИС\PYTHON\sem9\venv\lib\site-packages\telegram\vendor\ptb_urllib3\urllib3\connectionpool.py", line 614, in urlopen
    httplib_response = self._make_request(conn, method, url,
  File "C:\Users\MRU024\Desktop\ДЕНИС\PYTHON\sem9\venv\lib\site-packages\telegram\vendor\ptb_urllib3\urllib3\connectionpool.py", line 404, in _make_request
    self._raise_timeout(err=e, url=url, timeout_value=read_timeout,
  File "C:\Users\MRU024\Desktop\ДЕНИС\PYTHON\sem9\venv\lib\site-packages\telegram\vendor\ptb_urllib3\urllib3\connectionpool.py", line 321, in _raise_timeout
    raise exc_cls(*args)
telegram.vendor.ptb_urllib3.urllib3.exceptions.ReadTimeoutError: HTTPSConnectionPool(host='api.telegram.org', port=443): Read timed out. (read timeout=5.0)

The above exception was the direct cause of the following exception:

Traceback (most recent call last):
  File "C:\Users\MRU024\Desktop\ДЕНИС\PYTHON\sem9\venv\lib\site-packages\telegram\ext\dispatcher.py", line 557, in process_update
    handler.handle_update(update, self, check, context)
  File "C:\Users\MRU024\Desktop\ДЕНИС\PYTHON\sem9\venv\lib\site-packages\telegram\ext\conversationhandler.py", line 627, in handle_update
    new_state = handler.handle_update(update, dispatcher, check_result, context)
  File "C:\Users\MRU024\Desktop\ДЕНИС\PYTHON\sem9\venv\lib\site-packages\telegram\ext\handler.py", line 199, in handle_update
    return self.callback(update, context)
  File "C:\Users\MRU024\Desktop\ДЕНИС\PYTHON\sem9\func.py", line 69, in work
    update.message.reply_text(f'{x} {znak} {y} = {x/y}')
  File "C:\Users\MRU024\Desktop\ДЕНИС\PYTHON\sem9\venv\lib\site-packages\telegram\message.py", line 912, in reply_text
    return self.bot.send_message(
  File "C:\Users\MRU024\Desktop\ДЕНИС\PYTHON\sem9\venv\lib\site-packages\telegram\bot.py", line 133, in decorator
    result = func(*args, **kwargs)
  File "C:\Users\MRU024\Desktop\ДЕНИС\PYTHON\sem9\venv\lib\site-packages\telegram\bot.py", line 525, in send_message
    return self._message(  # type: ignore[return-value]
  File "C:\Users\MRU024\Desktop\ДЕНИС\PYTHON\sem9\venv\lib\site-packages\telegram\ext\extbot.py", line 202, in _message
    result = super()._message(
  File "C:\Users\MRU024\Desktop\ДЕНИС\PYTHON\sem9\venv\lib\site-packages\telegram\bot.py", line 339, in _message
    result = self._post(endpoint, data, timeout=timeout, api_kwargs=api_kwargs)
  File "C:\Users\MRU024\Desktop\ДЕНИС\PYTHON\sem9\venv\lib\site-packages\telegram\bot.py", line 298, in _post
    return self.request.post(
  File "C:\Users\MRU024\Desktop\ДЕНИС\PYTHON\sem9\venv\lib\site-packages\telegram\utils\request.py", line 361, in post
    result = self._request_wrapper(
  File "C:\Users\MRU024\Desktop\ДЕНИС\PYTHON\sem9\venv\lib\site-packages\telegram\utils\request.py", line 261, in _request_wrapper
    raise TimedOut() from error
telegram.error.TimedOut: Timed out
2022/10/31, 09:02:16 WARNING Retrying (Retry(total=2, connect=None, read=None, redirect=None)) after connection broken by 'NewConnectionError('<telegram.vendor.ptb_urllib3.urllib3.connection.VerifiedHTTPSConnection object at 0x000001AF9BB58B50>: Failed to establish a new connection: [Errno 11001] getaddrinfo failed')': /bot5730723225:AAGajXgHJLVuoFKOpme70EYRP_XLqANOsKY/getUpdates
2022/10/31, 09:02:16 WARNING Retrying (Retry(total=1, connect=None, read=None, redirect=None)) after connection broken by 'NewConnectionError('<telegram.vendor.ptb_urllib3.urllib3.connection.VerifiedHTTPSConnection object at 0x000001AF9BB58A00>: Failed to establish a new connection: [Errno 11001] getaddrinfo failed')': /bot5730723225:AAGajXgHJLVuoFKOpme70EYRP_XLqANOsKY/getUpdates
2022/10/31, 09:02:16 WARNING Retrying (Retry(total=0, connect=None, read=None, redirect=None)) after connection broken by 'NewConnectionError('<telegram.vendor.ptb_urllib3.urllib3.connection.VerifiedHTTPSConnection object at 0x000001AF9BB588B0>: Failed to establish a new connection: [Errno 11001] getaddrinfo failed')': /bot5730723225:AAGajXgHJLVuoFKOpme70EYRP_XLqANOsKY/getUpdates
2022/10/31, 09:02:16 ERROR Error while getting Updates: urllib3 HTTPError HTTPSConnectionPool(host='api.telegram.org', port=443): Max retries exceeded with url: /bot5730723225:AAGajXgHJLVuoFKOpme70EYRP_XLqANOsKY/getUpdates (Caused by NewConnectionError('<telegram.vendor.ptb_urllib3.urllib3.connection.VerifiedHTTPSConnection object at 0x000001AF9BB58760>: Failed to establish a new connection: [Errno 11001] getaddrinfo failed'))
2022/10/31, 09:02:16 ERROR No error handlers are registered, logging exception.
Traceback (most recent call last):
  File "C:\Users\MRU024\Desktop\ДЕНИС\PYTHON\sem9\venv\lib\site-packages\telegram\vendor\ptb_urllib3\urllib3\connection.py", line 140, in _new_conn
    conn = connection.create_connection(
  File "C:\Users\MRU024\Desktop\ДЕНИС\PYTHON\sem9\venv\lib\site-packages\telegram\vendor\ptb_urllib3\urllib3\util\connection.py", line 60, in create_connection
    for res in socket.getaddrinfo(host, port, family, socket.SOCK_STREAM):
  File "C:\Users\MRU024\AppData\Local\Programs\Python\Python310\lib\socket.py", line 955, in getaddrinfo
    for res in _socket.getaddrinfo(host, port, family, type, proto, flags):
socket.gaierror: [Errno 11001] getaddrinfo failed

During handling of the above exception, another exception occurred:

Traceback (most recent call last):
  File "C:\Users\MRU024\Desktop\ДЕНИС\PYTHON\sem9\venv\lib\site-packages\telegram\vendor\ptb_urllib3\urllib3\connectionpool.py", line 614, in urlopen
    httplib_response = self._make_request(conn, method, url,
  File "C:\Users\MRU024\Desktop\ДЕНИС\PYTHON\sem9\venv\lib\site-packages\telegram\vendor\ptb_urllib3\urllib3\connectionpool.py", line 360, in _make_request
    self._validate_conn(conn)
  File "C:\Users\MRU024\Desktop\ДЕНИС\PYTHON\sem9\venv\lib\site-packages\telegram\vendor\ptb_urllib3\urllib3\connectionpool.py", line 857, in _validate_conn
    super(HTTPSConnectionPool, self)._validate_conn(conn)
  File "C:\Users\MRU024\Desktop\ДЕНИС\PYTHON\sem9\venv\lib\site-packages\telegram\vendor\ptb_urllib3\urllib3\connectionpool.py", line 289, in _validate_conn
    conn.connect()
  File "C:\Users\MRU024\Desktop\ДЕНИС\PYTHON\sem9\venv\lib\site-packages\telegram\vendor\ptb_urllib3\urllib3\connection.py", line 284, in connect
    conn = self._new_conn()
  File "C:\Users\MRU024\Desktop\ДЕНИС\PYTHON\sem9\venv\lib\site-packages\telegram\vendor\ptb_urllib3\urllib3\connection.py", line 149, in _new_conn
    raise NewConnectionError(
telegram.vendor.ptb_urllib3.urllib3.exceptions.NewConnectionError: <telegram.vendor.ptb_urllib3.urllib3.connection.VerifiedHTTPSConnection object at 0x000001AF9BB58760>: Failed to establish a new connection: [Errno 11001] getaddrinfo failed

During handling of the above exception, another exception occurred:

Traceback (most recent call last):
  File "C:\Users\MRU024\Desktop\ДЕНИС\PYTHON\sem9\venv\lib\site-packages\telegram\utils\request.py", line 259, in _request_wrapper
    resp = self._con_pool.request(*args, **kwargs)
  File "C:\Users\MRU024\Desktop\ДЕНИС\PYTHON\sem9\venv\lib\site-packages\telegram\vendor\ptb_urllib3\urllib3\request.py", line 68, in request
    return self.request_encode_body(method, url, fields=fields,
  File "C:\Users\MRU024\Desktop\ДЕНИС\PYTHON\sem9\venv\lib\site-packages\telegram\vendor\ptb_urllib3\urllib3\request.py", line 148, in request_encode_body
    return self.urlopen(method, url, **extra_kw)
  File "C:\Users\MRU024\Desktop\ДЕНИС\PYTHON\sem9\venv\lib\site-packages\telegram\vendor\ptb_urllib3\urllib3\poolmanager.py", line 244, in urlopen
    response = conn.urlopen(method, u.request_uri, **kw)
  File "C:\Users\MRU024\Desktop\ДЕНИС\PYTHON\sem9\venv\lib\site-packages\telegram\vendor\ptb_urllib3\urllib3\connectionpool.py", line 691, in urlopen
    return self.urlopen(method, url, body, headers, retries,
  File "C:\Users\MRU024\Desktop\ДЕНИС\PYTHON\sem9\venv\lib\site-packages\telegram\vendor\ptb_urllib3\urllib3\connectionpool.py", line 691, in urlopen
    return self.urlopen(method, url, body, headers, retries,
  File "C:\Users\MRU024\Desktop\ДЕНИС\PYTHON\sem9\venv\lib\site-packages\telegram\vendor\ptb_urllib3\urllib3\connectionpool.py", line 691, in urlopen
    return self.urlopen(method, url, body, headers, retries,
  File "C:\Users\MRU024\Desktop\ДЕНИС\PYTHON\sem9\venv\lib\site-packages\telegram\vendor\ptb_urllib3\urllib3\connectionpool.py", line 665, in urlopen
    retries = retries.increment(method, url, error=e, _pool=self,
  File "C:\Users\MRU024\Desktop\ДЕНИС\PYTHON\sem9\venv\lib\site-packages\telegram\vendor\ptb_urllib3\urllib3\util\retry.py", line 376, in increment
    raise MaxRetryError(_pool, url, error or ResponseError(cause))
telegram.vendor.ptb_urllib3.urllib3.exceptions.MaxRetryError: HTTPSConnectionPool(host='api.telegram.org', port=443): Max retries exceeded with url: /bot5730723225:AAGajXgHJLVuoFKOpme70EYRP_XLqANOsKY/getUpdates (Caused by NewConnectionError('<telegram.vendor.ptb_urllib3.urllib3.connection.VerifiedHTTPSConnection object at 0x000001AF9BB58760>: Failed to establish a new connection: [Errno 11001] getaddrinfo failed'))

The above exception was the direct cause of the following exception:

Traceback (most recent call last):
  File "C:\Users\MRU024\Desktop\ДЕНИС\PYTHON\sem9\venv\lib\site-packages\telegram\ext\updater.py", line 646, in _network_loop_retry
    if not action_cb():
  File "C:\Users\MRU024\Desktop\ДЕНИС\PYTHON\sem9\venv\lib\site-packages\telegram\ext\updater.py", line 597, in polling_action_cb
    updates = self.bot.get_updates(
  File "C:\Users\MRU024\Desktop\ДЕНИС\PYTHON\sem9\venv\lib\site-packages\telegram\ext\extbot.py", line 226, in get_updates
    updates = super().get_updates(
  File "C:\Users\MRU024\Desktop\ДЕНИС\PYTHON\sem9\venv\lib\site-packages\telegram\bot.py", line 133, in decorator
    result = func(*args, **kwargs)
  File "C:\Users\MRU024\Desktop\ДЕНИС\PYTHON\sem9\venv\lib\site-packages\telegram\bot.py", line 3057, in get_updates
    self._post(
  File "C:\Users\MRU024\Desktop\ДЕНИС\PYTHON\sem9\venv\lib\site-packages\telegram\bot.py", line 298, in _post
    return self.request.post(
  File "C:\Users\MRU024\Desktop\ДЕНИС\PYTHON\sem9\venv\lib\site-packages\telegram\utils\request.py", line 361, in post
    result = self._request_wrapper(
  File "C:\Users\MRU024\Desktop\ДЕНИС\PYTHON\sem9\venv\lib\site-packages\telegram\utils\request.py", line 265, in _request_wrapper
    raise NetworkError(f'urllib3 HTTPError {error}') from error
telegram.error.NetworkError: urllib3 HTTPError HTTPSConnectionPool(host='api.telegram.org', port=443): Max retries exceeded with url: /bot5730723225:AAGajXgHJLVuoFKOpme70EYRP_XLqANOsKY/getUpdates (Caused by NewConnectionError('<telegram.vendor.ptb_urllib3.urllib3.connection.VerifiedHTTPSConnection object at 0x000001AF9BB58760>: Failed to establish a new connection: [Errno 11001] getaddrinfo failed'))
2022/10/31, 09:02:17 WARNING Retrying (Retry(total=2, connect=None, read=None, redirect=None)) after connection broken by 'NewConnectionError('<telegram.vendor.ptb_urllib3.urllib3.connection.VerifiedHTTPSConnection object at 0x000001AF9BB58550>: Failed to establish a new connection: [Errno 11001] getaddrinfo failed')': /bot5730723225:AAGajXgHJLVuoFKOpme70EYRP_XLqANOsKY/getUpdates
2022/10/31, 09:02:17 WARNING Retrying (Retry(total=1, connect=None, read=None, redirect=None)) after connection broken by 'NewConnectionError('<telegram.vendor.ptb_urllib3.urllib3.connection.VerifiedHTTPSConnection object at 0x000001AF9BB585B0>: Failed to establish a new connection: [Errno 11001] getaddrinfo failed')': /bot5730723225:AAGajXgHJLVuoFKOpme70EYRP_XLqANOsKY/getUpdates
2022/10/31, 09:02:17 WARNING Retrying (Retry(total=0, connect=None, read=None, redirect=None)) after connection broken by 'NewConnectionError('<telegram.vendor.ptb_urllib3.urllib3.connection.VerifiedHTTPSConnection object at 0x000001AF9BB582E0>: Failed to establish a new connection: [Errno 11001] getaddrinfo failed')': /bot5730723225:AAGajXgHJLVuoFKOpme70EYRP_XLqANOsKY/getUpdates
2022/10/31, 09:02:17 ERROR Error while getting Updates: urllib3 HTTPError HTTPSConnectionPool(host='api.telegram.org', port=443): Max retries exceeded with url: /bot5730723225:AAGajXgHJLVuoFKOpme70EYRP_XLqANOsKY/getUpdates (Caused by NewConnectionError('<telegram.vendor.ptb_urllib3.urllib3.connection.VerifiedHTTPSConnection object at 0x000001AF9BB5A920>: Failed to establish a new connection: [Errno 11001] getaddrinfo failed'))
2022/10/31, 09:02:17 ERROR No error handlers are registered, logging exception.
Traceback (most recent call last):
  File "C:\Users\MRU024\Desktop\ДЕНИС\PYTHON\sem9\venv\lib\site-packages\telegram\vendor\ptb_urllib3\urllib3\connection.py", line 140, in _new_conn
    conn = connection.create_connection(
  File "C:\Users\MRU024\Desktop\ДЕНИС\PYTHON\sem9\venv\lib\site-packages\telegram\vendor\ptb_urllib3\urllib3\util\connection.py", line 60, in create_connection
    for res in socket.getaddrinfo(host, port, family, socket.SOCK_STREAM):
  File "C:\Users\MRU024\AppData\Local\Programs\Python\Python310\lib\socket.py", line 955, in getaddrinfo
    for res in _socket.getaddrinfo(host, port, family, type, proto, flags):
socket.gaierror: [Errno 11001] getaddrinfo failed

During handling of the above exception, another exception occurred:

Traceback (most recent call last):
  File "C:\Users\MRU024\Desktop\ДЕНИС\PYTHON\sem9\venv\lib\site-packages\telegram\vendor\ptb_urllib3\urllib3\connectionpool.py", line 614, in urlopen
    httplib_response = self._make_request(conn, method, url,
  File "C:\Users\MRU024\Desktop\ДЕНИС\PYTHON\sem9\venv\lib\site-packages\telegram\vendor\ptb_urllib3\urllib3\connectionpool.py", line 360, in _make_request
    self._validate_conn(conn)
  File "C:\Users\MRU024\Desktop\ДЕНИС\PYTHON\sem9\venv\lib\site-packages\telegram\vendor\ptb_urllib3\urllib3\connectionpool.py", line 857, in _validate_conn
    super(HTTPSConnectionPool, self)._validate_conn(conn)
  File "C:\Users\MRU024\Desktop\ДЕНИС\PYTHON\sem9\venv\lib\site-packages\telegram\vendor\ptb_urllib3\urllib3\connectionpool.py", line 289, in _validate_conn
    conn.connect()
  File "C:\Users\MRU024\Desktop\ДЕНИС\PYTHON\sem9\venv\lib\site-packages\telegram\vendor\ptb_urllib3\urllib3\connection.py", line 284, in connect
    conn = self._new_conn()
  File "C:\Users\MRU024\Desktop\ДЕНИС\PYTHON\sem9\venv\lib\site-packages\telegram\vendor\ptb_urllib3\urllib3\connection.py", line 149, in _new_conn
    raise NewConnectionError(
telegram.vendor.ptb_urllib3.urllib3.exceptions.NewConnectionError: <telegram.vendor.ptb_urllib3.urllib3.connection.VerifiedHTTPSConnection object at 0x000001AF9BB5A920>: Failed to establish a new connection: [Errno 11001] getaddrinfo failed

During handling of the above exception, another exception occurred:

Traceback (most recent call last):
  File "C:\Users\MRU024\Desktop\ДЕНИС\PYTHON\sem9\venv\lib\site-packages\telegram\utils\request.py", line 259, in _request_wrapper
    resp = self._con_pool.request(*args, **kwargs)
  File "C:\Users\MRU024\Desktop\ДЕНИС\PYTHON\sem9\venv\lib\site-packages\telegram\vendor\ptb_urllib3\urllib3\request.py", line 68, in request
    return self.request_encode_body(method, url, fields=fields,
  File "C:\Users\MRU024\Desktop\ДЕНИС\PYTHON\sem9\venv\lib\site-packages\telegram\vendor\ptb_urllib3\urllib3\request.py", line 148, in request_encode_body
    return self.urlopen(method, url, **extra_kw)
  File "C:\Users\MRU024\Desktop\ДЕНИС\PYTHON\sem9\venv\lib\site-packages\telegram\vendor\ptb_urllib3\urllib3\poolmanager.py", line 244, in urlopen
    response = conn.urlopen(method, u.request_uri, **kw)
  File "C:\Users\MRU024\Desktop\ДЕНИС\PYTHON\sem9\venv\lib\site-packages\telegram\vendor\ptb_urllib3\urllib3\connectionpool.py", line 691, in urlopen
    return self.urlopen(method, url, body, headers, retries,
  File "C:\Users\MRU024\Desktop\ДЕНИС\PYTHON\sem9\venv\lib\site-packages\telegram\vendor\ptb_urllib3\urllib3\connectionpool.py", line 691, in urlopen
    return self.urlopen(method, url, body, headers, retries,
  File "C:\Users\MRU024\Desktop\ДЕНИС\PYTHON\sem9\venv\lib\site-packages\telegram\vendor\ptb_urllib3\urllib3\connectionpool.py", line 691, in urlopen
    return self.urlopen(method, url, body, headers, retries,
  File "C:\Users\MRU024\Desktop\ДЕНИС\PYTHON\sem9\venv\lib\site-packages\telegram\vendor\ptb_urllib3\urllib3\connectionpool.py", line 665, in urlopen
    retries = retries.increment(method, url, error=e, _pool=self,
  File "C:\Users\MRU024\Desktop\ДЕНИС\PYTHON\sem9\venv\lib\site-packages\telegram\vendor\ptb_urllib3\urllib3\util\retry.py", line 376, in increment
    raise MaxRetryError(_pool, url, error or ResponseError(cause))
telegram.vendor.ptb_urllib3.urllib3.exceptions.MaxRetryError: HTTPSConnectionPool(host='api.telegram.org', port=443): Max retries exceeded with url: /bot5730723225:AAGajXgHJLVuoFKOpme70EYRP_XLqANOsKY/getUpdates (Caused by NewConnectionError('<telegram.vendor.ptb_urllib3.urllib3.connection.VerifiedHTTPSConnection object at 0x000001AF9BB5A920>: Failed to establish a new connection: [Errno 11001] getaddrinfo failed'))

The above exception was the direct cause of the following exception:

Traceback (most recent call last):
  File "C:\Users\MRU024\Desktop\ДЕНИС\PYTHON\sem9\venv\lib\site-packages\telegram\ext\updater.py", line 646, in _network_loop_retry
    if not action_cb():
  File "C:\Users\MRU024\Desktop\ДЕНИС\PYTHON\sem9\venv\lib\site-packages\telegram\ext\updater.py", line 597, in polling_action_cb
    updates = self.bot.get_updates(
  File "C:\Users\MRU024\Desktop\ДЕНИС\PYTHON\sem9\venv\lib\site-packages\telegram\ext\extbot.py", line 226, in get_updates
    updates = super().get_updates(
  File "C:\Users\MRU024\Desktop\ДЕНИС\PYTHON\sem9\venv\lib\site-packages\telegram\bot.py", line 133, in decorator
    result = func(*args, **kwargs)
  File "C:\Users\MRU024\Desktop\ДЕНИС\PYTHON\sem9\venv\lib\site-packages\telegram\bot.py", line 3057, in get_updates
    self._post(
  File "C:\Users\MRU024\Desktop\ДЕНИС\PYTHON\sem9\venv\lib\site-packages\telegram\bot.py", line 298, in _post
    return self.request.post(
  File "C:\Users\MRU024\Desktop\ДЕНИС\PYTHON\sem9\venv\lib\site-packages\telegram\utils\request.py", line 361, in post
    result = self._request_wrapper(
  File "C:\Users\MRU024\Desktop\ДЕНИС\PYTHON\sem9\venv\lib\site-packages\telegram\utils\request.py", line 265, in _request_wrapper
    raise NetworkError(f'urllib3 HTTPError {error}') from error
telegram.error.NetworkError: urllib3 HTTPError HTTPSConnectionPool(host='api.telegram.org', port=443): Max retries exceeded with url: /bot5730723225:AAGajXgHJLVuoFKOpme70EYRP_XLqANOsKY/getUpdates (Caused by NewConnectionError('<telegram.vendor.ptb_urllib3.urllib3.connection.VerifiedHTTPSConnection object at 0x000001AF9BB5A920>: Failed to establish a new connection: [Errno 11001] getaddrinfo failed'))
2022/10/31, 09:02:18 WARNING Retrying (Retry(total=2, connect=None, read=None, redirect=None)) after connection broken by 'NewConnectionError('<telegram.vendor.ptb_urllib3.urllib3.connection.VerifiedHTTPSConnection object at 0x000001AF9BB585E0>: Failed to establish a new connection: [Errno 11001] getaddrinfo failed')': /bot5730723225:AAGajXgHJLVuoFKOpme70EYRP_XLqANOsKY/getUpdates
2022/10/31, 09:02:18 WARNING Retrying (Retry(total=1, connect=None, read=None, redirect=None)) after connection broken by 'NewConnectionError('<telegram.vendor.ptb_urllib3.urllib3.connection.VerifiedHTTPSConnection object at 0x000001AF9BB5AA40>: Failed to establish a new connection: [Errno 11001] getaddrinfo failed')': /bot5730723225:AAGajXgHJLVuoFKOpme70EYRP_XLqANOsKY/getUpdates
2022/10/31, 09:02:18 WARNING Retrying (Retry(total=0, connect=None, read=None, redirect=None)) after connection broken by 'NewConnectionError('<telegram.vendor.ptb_urllib3.urllib3.connection.VerifiedHTTPSConnection object at 0x000001AF9BB59600>: Failed to establish a new connection: [Errno 11001] getaddrinfo failed')': /bot5730723225:AAGajXgHJLVuoFKOpme70EYRP_XLqANOsKY/getUpdates
2022/10/31, 09:02:18 ERROR Error while getting Updates: urllib3 HTTPError HTTPSConnectionPool(host='api.telegram.org', port=443): Max retries exceeded with url: /bot5730723225:AAGajXgHJLVuoFKOpme70EYRP_XLqANOsKY/getUpdates (Caused by NewConnectionError('<telegram.vendor.ptb_urllib3.urllib3.connection.VerifiedHTTPSConnection object at 0x000001AF9BB58190>: Failed to establish a new connection: [Errno 11001] getaddrinfo failed'))
2022/10/31, 09:02:18 ERROR No error handlers are registered, logging exception.
Traceback (most recent call last):
  File "C:\Users\MRU024\Desktop\ДЕНИС\PYTHON\sem9\venv\lib\site-packages\telegram\vendor\ptb_urllib3\urllib3\connection.py", line 140, in _new_conn
    conn = connection.create_connection(
  File "C:\Users\MRU024\Desktop\ДЕНИС\PYTHON\sem9\venv\lib\site-packages\telegram\vendor\ptb_urllib3\urllib3\util\connection.py", line 60, in create_connection
    for res in socket.getaddrinfo(host, port, family, socket.SOCK_STREAM):
  File "C:\Users\MRU024\AppData\Local\Programs\Python\Python310\lib\socket.py", line 955, in getaddrinfo
    for res in _socket.getaddrinfo(host, port, family, type, proto, flags):
socket.gaierror: [Errno 11001] getaddrinfo failed

During handling of the above exception, another exception occurred:

Traceback (most recent call last):
  File "C:\Users\MRU024\Desktop\ДЕНИС\PYTHON\sem9\venv\lib\site-packages\telegram\vendor\ptb_urllib3\urllib3\connectionpool.py", line 614, in urlopen
    httplib_response = self._make_request(conn, method, url,
  File "C:\Users\MRU024\Desktop\ДЕНИС\PYTHON\sem9\venv\lib\site-packages\telegram\vendor\ptb_urllib3\urllib3\connectionpool.py", line 360, in _make_request
    self._validate_conn(conn)
  File "C:\Users\MRU024\Desktop\ДЕНИС\PYTHON\sem9\venv\lib\site-packages\telegram\vendor\ptb_urllib3\urllib3\connectionpool.py", line 857, in _validate_conn
    super(HTTPSConnectionPool, self)._validate_conn(conn)
  File "C:\Users\MRU024\Desktop\ДЕНИС\PYTHON\sem9\venv\lib\site-packages\telegram\vendor\ptb_urllib3\urllib3\connectionpool.py", line 289, in _validate_conn
    conn.connect()
  File "C:\Users\MRU024\Desktop\ДЕНИС\PYTHON\sem9\venv\lib\site-packages\telegram\vendor\ptb_urllib3\urllib3\connection.py", line 284, in connect
    conn = self._new_conn()
  File "C:\Users\MRU024\Desktop\ДЕНИС\PYTHON\sem9\venv\lib\site-packages\telegram\vendor\ptb_urllib3\urllib3\connection.py", line 149, in _new_conn
    raise NewConnectionError(
telegram.vendor.ptb_urllib3.urllib3.exceptions.NewConnectionError: <telegram.vendor.ptb_urllib3.urllib3.connection.VerifiedHTTPSConnection object at 0x000001AF9BB58190>: Failed to establish a new connection: [Errno 11001] getaddrinfo failed

During handling of the above exception, another exception occurred:

Traceback (most recent call last):
  File "C:\Users\MRU024\Desktop\ДЕНИС\PYTHON\sem9\venv\lib\site-packages\telegram\utils\request.py", line 259, in _request_wrapper
    resp = self._con_pool.request(*args, **kwargs)
  File "C:\Users\MRU024\Desktop\ДЕНИС\PYTHON\sem9\venv\lib\site-packages\telegram\vendor\ptb_urllib3\urllib3\request.py", line 68, in request
    return self.request_encode_body(method, url, fields=fields,
  File "C:\Users\MRU024\Desktop\ДЕНИС\PYTHON\sem9\venv\lib\site-packages\telegram\vendor\ptb_urllib3\urllib3\request.py", line 148, in request_encode_body
    return self.urlopen(method, url, **extra_kw)
  File "C:\Users\MRU024\Desktop\ДЕНИС\PYTHON\sem9\venv\lib\site-packages\telegram\vendor\ptb_urllib3\urllib3\poolmanager.py", line 244, in urlopen
    response = conn.urlopen(method, u.request_uri, **kw)
  File "C:\Users\MRU024\Desktop\ДЕНИС\PYTHON\sem9\venv\lib\site-packages\telegram\vendor\ptb_urllib3\urllib3\connectionpool.py", line 691, in urlopen
    return self.urlopen(method, url, body, headers, retries,
  File "C:\Users\MRU024\Desktop\ДЕНИС\PYTHON\sem9\venv\lib\site-packages\telegram\vendor\ptb_urllib3\urllib3\connectionpool.py", line 691, in urlopen
    return self.urlopen(method, url, body, headers, retries,
  File "C:\Users\MRU024\Desktop\ДЕНИС\PYTHON\sem9\venv\lib\site-packages\telegram\vendor\ptb_urllib3\urllib3\connectionpool.py", line 691, in urlopen
    return self.urlopen(method, url, body, headers, retries,
  File "C:\Users\MRU024\Desktop\ДЕНИС\PYTHON\sem9\venv\lib\site-packages\telegram\vendor\ptb_urllib3\urllib3\connectionpool.py", line 665, in urlopen
    retries = retries.increment(method, url, error=e, _pool=self,
  File "C:\Users\MRU024\Desktop\ДЕНИС\PYTHON\sem9\venv\lib\site-packages\telegram\vendor\ptb_urllib3\urllib3\util\retry.py", line 376, in increment
    raise MaxRetryError(_pool, url, error or ResponseError(cause))
telegram.vendor.ptb_urllib3.urllib3.exceptions.MaxRetryError: HTTPSConnectionPool(host='api.telegram.org', port=443): Max retries exceeded with url: /bot5730723225:AAGajXgHJLVuoFKOpme70EYRP_XLqANOsKY/getUpdates (Caused by NewConnectionError('<telegram.vendor.ptb_urllib3.urllib3.connection.VerifiedHTTPSConnection object at 0x000001AF9BB58190>: Failed to establish a new connection: [Errno 11001] getaddrinfo failed'))

The above exception was the direct cause of the following exception:

Traceback (most recent call last):
  File "C:\Users\MRU024\Desktop\ДЕНИС\PYTHON\sem9\venv\lib\site-packages\telegram\ext\updater.py", line 646, in _network_loop_retry
    if not action_cb():
  File "C:\Users\MRU024\Desktop\ДЕНИС\PYTHON\sem9\venv\lib\site-packages\telegram\ext\updater.py", line 597, in polling_action_cb
    updates = self.bot.get_updates(
  File "C:\Users\MRU024\Desktop\ДЕНИС\PYTHON\sem9\venv\lib\site-packages\telegram\ext\extbot.py", line 226, in get_updates
    updates = super().get_updates(
  File "C:\Users\MRU024\Desktop\ДЕНИС\PYTHON\sem9\venv\lib\site-packages\telegram\bot.py", line 133, in decorator
    result = func(*args, **kwargs)
  File "C:\Users\MRU024\Desktop\ДЕНИС\PYTHON\sem9\venv\lib\site-packages\telegram\bot.py", line 3057, in get_updates
    self._post(
  File "C:\Users\MRU024\Desktop\ДЕНИС\PYTHON\sem9\venv\lib\site-packages\telegram\bot.py", line 298, in _post
    return self.request.post(
  File "C:\Users\MRU024\Desktop\ДЕНИС\PYTHON\sem9\venv\lib\site-packages\telegram\utils\request.py", line 361, in post
    result = self._request_wrapper(
  File "C:\Users\MRU024\Desktop\ДЕНИС\PYTHON\sem9\venv\lib\site-packages\telegram\utils\request.py", line 265, in _request_wrapper
    raise NetworkError(f'urllib3 HTTPError {error}') from error
telegram.error.NetworkError: urllib3 HTTPError HTTPSConnectionPool(host='api.telegram.org', port=443): Max retries exceeded with url: /bot5730723225:AAGajXgHJLVuoFKOpme70EYRP_XLqANOsKY/getUpdates (Caused by NewConnectionError('<telegram.vendor.ptb_urllib3.urllib3.connection.VerifiedHTTPSConnection object at 0x000001AF9BB58190>: Failed to establish a new connection: [Errno 11001] getaddrinfo failed'))
2022/10/31, 09:02:56 ERROR Error while getting Updates: urllib3 HTTPError ('Connection aborted.', RemoteDisconnected('Remote end closed connection without response'))
2022/10/31, 09:02:56 ERROR No error handlers are registered, logging exception.
Traceback (most recent call last):
  File "C:\Users\MRU024\Desktop\ДЕНИС\PYTHON\sem9\venv\lib\site-packages\telegram\vendor\ptb_urllib3\urllib3\connectionpool.py", line 614, in urlopen
    httplib_response = self._make_request(conn, method, url,
  File "C:\Users\MRU024\Desktop\ДЕНИС\PYTHON\sem9\venv\lib\site-packages\telegram\vendor\ptb_urllib3\urllib3\connectionpool.py", line 402, in _make_request
    six.raise_from(e, None)
  File "<string>", line 2, in raise_from
  File "C:\Users\MRU024\Desktop\ДЕНИС\PYTHON\sem9\venv\lib\site-packages\telegram\vendor\ptb_urllib3\urllib3\connectionpool.py", line 398, in _make_request
    httplib_response = conn.getresponse()
  File "C:\Users\MRU024\AppData\Local\Programs\Python\Python310\lib\http\client.py", line 1374, in getresponse
    response.begin()
  File "C:\Users\MRU024\AppData\Local\Programs\Python\Python310\lib\http\client.py", line 318, in begin
    version, status, reason = self._read_status()
  File "C:\Users\MRU024\AppData\Local\Programs\Python\Python310\lib\http\client.py", line 287, in _read_status
    raise RemoteDisconnected("Remote end closed connection without"
http.client.RemoteDisconnected: Remote end closed connection without response

During handling of the above exception, another exception occurred:

Traceback (most recent call last):
  File "C:\Users\MRU024\Desktop\ДЕНИС\PYTHON\sem9\venv\lib\site-packages\telegram\utils\request.py", line 259, in _request_wrapper
    resp = self._con_pool.request(*args, **kwargs)
  File "C:\Users\MRU024\Desktop\ДЕНИС\PYTHON\sem9\venv\lib\site-packages\telegram\vendor\ptb_urllib3\urllib3\request.py", line 68, in request
    return self.request_encode_body(method, url, fields=fields,
  File "C:\Users\MRU024\Desktop\ДЕНИС\PYTHON\sem9\venv\lib\site-packages\telegram\vendor\ptb_urllib3\urllib3\request.py", line 148, in request_encode_body
    return self.urlopen(method, url, **extra_kw)
  File "C:\Users\MRU024\Desktop\ДЕНИС\PYTHON\sem9\venv\lib\site-packages\telegram\vendor\ptb_urllib3\urllib3\poolmanager.py", line 244, in urlopen
    response = conn.urlopen(method, u.request_uri, **kw)
  File "C:\Users\MRU024\Desktop\ДЕНИС\PYTHON\sem9\venv\lib\site-packages\telegram\vendor\ptb_urllib3\urllib3\connectionpool.py", line 665, in urlopen
    retries = retries.increment(method, url, error=e, _pool=self,
  File "C:\Users\MRU024\Desktop\ДЕНИС\PYTHON\sem9\venv\lib\site-packages\telegram\vendor\ptb_urllib3\urllib3\util\retry.py", line 347, in increment
    raise six.reraise(type(error), error, _stacktrace)
  File "C:\Users\MRU024\Desktop\ДЕНИС\PYTHON\sem9\venv\lib\site-packages\telegram\vendor\ptb_urllib3\urllib3\packages\six.py", line 685, in reraise
    raise value.with_traceback(tb)
  File "C:\Users\MRU024\Desktop\ДЕНИС\PYTHON\sem9\venv\lib\site-packages\telegram\vendor\ptb_urllib3\urllib3\connectionpool.py", line 614, in urlopen
    httplib_response = self._make_request(conn, method, url,
  File "C:\Users\MRU024\Desktop\ДЕНИС\PYTHON\sem9\venv\lib\site-packages\telegram\vendor\ptb_urllib3\urllib3\connectionpool.py", line 402, in _make_request
    six.raise_from(e, None)
  File "<string>", line 2, in raise_from
  File "C:\Users\MRU024\Desktop\ДЕНИС\PYTHON\sem9\venv\lib\site-packages\telegram\vendor\ptb_urllib3\urllib3\connectionpool.py", line 398, in _make_request
    httplib_response = conn.getresponse()
  File "C:\Users\MRU024\AppData\Local\Programs\Python\Python310\lib\http\client.py", line 1374, in getresponse
    response.begin()
  File "C:\Users\MRU024\AppData\Local\Programs\Python\Python310\lib\http\client.py", line 318, in begin
    version, status, reason = self._read_status()
  File "C:\Users\MRU024\AppData\Local\Programs\Python\Python310\lib\http\client.py", line 287, in _read_status
    raise RemoteDisconnected("Remote end closed connection without"
telegram.vendor.ptb_urllib3.urllib3.exceptions.ProtocolError: ('Connection aborted.', RemoteDisconnected('Remote end closed connection without response'))

The above exception was the direct cause of the following exception:

Traceback (most recent call last):
  File "C:\Users\MRU024\Desktop\ДЕНИС\PYTHON\sem9\venv\lib\site-packages\telegram\ext\updater.py", line 646, in _network_loop_retry
    if not action_cb():
  File "C:\Users\MRU024\Desktop\ДЕНИС\PYTHON\sem9\venv\lib\site-packages\telegram\ext\updater.py", line 597, in polling_action_cb
    updates = self.bot.get_updates(
  File "C:\Users\MRU024\Desktop\ДЕНИС\PYTHON\sem9\venv\lib\site-packages\telegram\ext\extbot.py", line 226, in get_updates
    updates = super().get_updates(
  File "C:\Users\MRU024\Desktop\ДЕНИС\PYTHON\sem9\venv\lib\site-packages\telegram\bot.py", line 133, in decorator
    result = func(*args, **kwargs)
  File "C:\Users\MRU024\Desktop\ДЕНИС\PYTHON\sem9\venv\lib\site-packages\telegram\bot.py", line 3057, in get_updates
    self._post(
  File "C:\Users\MRU024\Desktop\ДЕНИС\PYTHON\sem9\venv\lib\site-packages\telegram\bot.py", line 298, in _post
    return self.request.post(
  File "C:\Users\MRU024\Desktop\ДЕНИС\PYTHON\sem9\venv\lib\site-packages\telegram\utils\request.py", line 361, in post
    result = self._request_wrapper(
  File "C:\Users\MRU024\Desktop\ДЕНИС\PYTHON\sem9\venv\lib\site-packages\telegram\utils\request.py", line 265, in _request_wrapper
    raise NetworkError(f'urllib3 HTTPError {error}') from error
telegram.error.NetworkError: urllib3 HTTPError ('Connection aborted.', RemoteDisconnected('Remote end closed connection without response'))
2022/10/31, 09:24:14 INFO Received signal 2 (SIGINT), stopping...
2022/10/31, 09:24:14 INFO Scheduler has been shut down
2022/10/31, 09:24:19 WARNING Exiting immediately!
2022/10/31, 09:24:24 INFO Scheduler started
2022/10/31, 09:36:01 INFO Бот запущен None id 1095956902
2022/10/31, 09:36:04 INFO Пользователь выбрал: Выход.
2022/10/31, 09:36:04 INFO Завершение работы.
2022/10/31, 09:36:09 INFO Бот запущен None id 1095956902
2022/10/31, 09:36:12 INFO Пользователь выбрал работать
2022/10/31, 09:36:50 INFO Received signal 2 (SIGINT), stopping...
2022/10/31, 09:36:50 INFO Scheduler has been shut down
2022/10/31, 15:36:39 INFO Scheduler started
2022/10/31, 15:36:56 INFO Бот запущен None id 1095956902
2022/10/31, 15:36:59 INFO Пользователь выбрал работать
2022/10/31, 15:37:58 INFO Received signal 2 (SIGINT), stopping...
2022/10/31, 15:37:58 INFO Scheduler has been shut down
2022/10/31, 15:38:56 INFO Scheduler started
2022/10/31, 15:39:07 INFO Бот запущен None id 1095956902
2022/10/31, 15:39:09 INFO Пользователь выбрал работать
2022/10/31, 15:39:36 ERROR No error handlers are registered, logging exception.
Traceback (most recent call last):
  File "C:\Users\MRU024\Desktop\ДЕНИС\PYTHON\sem9\venv\lib\site-packages\telegram\ext\dispatcher.py", line 557, in process_update
    handler.handle_update(update, self, check, context)
  File "C:\Users\MRU024\Desktop\ДЕНИС\PYTHON\sem9\venv\lib\site-packages\telegram\ext\conversationhandler.py", line 627, in handle_update
    new_state = handler.handle_update(update, dispatcher, check_result, context)
  File "C:\Users\MRU024\Desktop\ДЕНИС\PYTHON\sem9\venv\lib\site-packages\telegram\ext\handler.py", line 199, in handle_update
    return self.callback(update, context)
  File "C:\Users\MRU024\Desktop\ДЕНИС\PYTHON\sem9\func.py", line 66, in work
    update.message.reply_text(f'{x} {znak} {y} = {x*y}')
TypeError: can't multiply sequence by non-int of type 'str'
2022/10/31, 15:49:57 INFO Received signal 2 (SIGINT), stopping...
2022/10/31, 15:49:57 INFO Scheduler has been shut down
2022/10/31, 16:33:26 INFO Scheduler started
2022/10/31, 16:33:41 INFO Бот запущен None id 1095956902
2022/10/31, 16:33:44 INFO Пользователь выбрал работать
2022/10/31, 16:34:00 ERROR No error handlers are registered, logging exception.
Traceback (most recent call last):
  File "C:\Users\MRU024\Desktop\ДЕНИС\PYTHON\sem9\venv\lib\site-packages\telegram\ext\dispatcher.py", line 557, in process_update
    handler.handle_update(update, self, check, context)
  File "C:\Users\MRU024\Desktop\ДЕНИС\PYTHON\sem9\venv\lib\site-packages\telegram\ext\conversationhandler.py", line 627, in handle_update
    new_state = handler.handle_update(update, dispatcher, check_result, context)
  File "C:\Users\MRU024\Desktop\ДЕНИС\PYTHON\sem9\venv\lib\site-packages\telegram\ext\handler.py", line 199, in handle_update
    return self.callback(update, context)
  File "C:\Users\MRU024\Desktop\ДЕНИС\PYTHON\sem9\func.py", line 51, in work
    if type(x, y) != int or type(x, y) != float:
TypeError: type() takes 1 or 3 arguments
2022/10/31, 16:38:52 INFO Received signal 2 (SIGINT), stopping...
2022/10/31, 16:38:52 INFO Scheduler has been shut down
2022/10/31, 16:38:54 WARNING Exiting immediately!
2022/10/31, 16:38:57 INFO Scheduler started
2022/10/31, 16:39:06 INFO Бот запущен None id 1095956902
2022/10/31, 16:39:08 INFO Пользователь выбрал работать
2022/10/31, 16:42:49 INFO Received signal 2 (SIGINT), stopping...
2022/10/31, 16:42:49 INFO Scheduler has been shut down
